Workbook

Sheet MOT OPPRINNELIGE TALL 
A1: ='NØKKELTALL OVERORDNET AVTALE '!A2 -> 46031 | B1: AU ESTIMAT | C1: SISTE REGNSKAP | D1: AVVIK | E1: % | F1: AU ESTIMAT | G1: SISTE REGNSKAP | H1: AVVIK | I1: %
B2: PLANTEDAMP | C2: PLANTEDAMP | E2: Endring | F2: GRO PRO | G2: GRO PRO | I2: Endring | J2: KOMMENTARER
A3: RESULTAT
A5: INNTEKTER | B5: 2500000 | C5: ='PLANTEDAMP AS 2022-2025'!O2 -> 2798754.8 | D5: =C5-B5 -> 298754.82 | E5: =D5/B5 -> 0.11950193 | F5: 700000 | G5: ='GRO PRO AS 2024 OG 2025 '!K3 -> 613516.26 | H5: =G5-F5 -> -86483.74 | I5: =H5/F5 -> -0.1235482
A6: TOTALT KOST INKL.SKATT | B6: =B5-B7 -> 2230964 | C6: =C5-C7 -> 2597695.8 | D6: =C6-B6 -> 366731.8 | E6: =D6/B6 -> 0.16438266 | F6: =F5-F7 -> 115356 | G6: =G5-G7 -> 719088.58 | H6: =G6-F6 -> 603732.58 | I6: =H6/F6 -> 5.233647 | J6: Sjekk oppdatert regnskap DataPro
A7: ÅRSRESULTAT | B7: =400000-130964 -> 269036 | C7: ='PLANTEDAMP AS 2022-2025'!O9 -> 201059.02 | D7: =C7-B7 -> -67976.98 | E7: =D7/B7 -> -0.25266871 | F7: 584644 | G7: ='GRO PRO AS 2024 OG 2025 '!K10 -> -105572.32 | H7: =G7-F7 -> -690216.32 | I7: =H7/F7 -> -1.1805754 | J7: Sjekk oppdatert regnskap DataPro
A10: BALANSE
A12: EGENKAPITAL | B12: 400000 | C12: ='PLANTEDAMP AS 2022-2025'!R9 -> 332022.73 | D12: =C12-B12 -> -67977.27 | E12: =D12/B12 -> -0.16994317 | F12: 700000 | G12: ='GRO PRO AS 2024 OG 2025 '!N10 -> 69783.22 | H12: =G12-F12 -> -630216.78 | I12: =H12/F12 -> -0.90030969 | J12: Sjekk oppdatert regnskap DataPro
A13: VARELAGER | B13: 1000000 | C13: ='PLANTEDAMP AS 2022-2025'!J12 -> 821605.63 | D13: =C13-B13 -> -178394.37 | E13: =D13/B13 -> -0.17839437 | F13: 700000 | G13: ='GRO PRO AS 2024 OG 2025 '!H12+'GRO PRO AS 2024 OG 2025 '!H13 -> 325112.85 | H13: =G13-F13 -> -374887.15 | I13: =H13/F13 -> -0.53555307 | J13: Sjekk oppdatert regnskap DataPro
A14: INNLÅN FRA AKSJONÆRER | B14: 600000 | C14: ='NØKKELTALL OVERORDNET AVTALE '!E14+'NØKKELTALL OVERORDNET AVTALE '!F14 -> 676690.86 | D14: =C14-B14 -> 76690.86 | E14: =D14/B14 -> 0.1278181 | F14: 50000 | G14: 50000 | H14: =G14-F14 -> 0 | I14: =H14/F14 -> 0 | J14: Sjekk oppdatert regnskap DataPro
A15: INTERNE MELLOMVÆRENDE NTO | B15: 0 | C15: ='NØKKELTALL OVERORDNET AVTALE '!B18 -> 194616.71 | G15: ='NØKKELTALL OVERORDNET AVTALE '!C18 -> -194616.71 | J15: GP er skylding PD 31 12 2025
A17: 1. Faktura fra PD til GP vedrørende overføring av lager er hensynstatt .
A18: 2. Har også avsatt for ytterligere overføring av lager fra PD til GP, Kr 55 000,-
A19: 3. Har fjernet ukurans nedskriving i begge lagre ref. samtale
A20: 4. Netto mellomværende er nå oppdatert ti lKr 194 617,- . Har lagt på Kr 55 000,- i overføring lager som ikke er fakturert fra PD mot GP . Må faktureres . Er med i telling GP , er redusert i PD

Sheet NØKKELTALL OVERORDNET AVTALE 
A1: GRUNNLAG INTERN PRISING AKSJER | B1: NØKKELTALL SELSKAPER PR. 31 12 2025 | H1: ANDEL AV NØKKELTALL | K1: PRISING BASERT PÅ 1/3 | N1: 1/3 PD | O1: 1/3 GP | P1: 1/3 TOTALT
A2: 46031
B3: PLANTEDAMP | C3: GRO PRO | D3: TOTALT | E3: Anders | F3: Yadgar | G3: Mitchell | H3: Anders | I3: Yadgar | J3: Mitchell | K3: Anders | L3: Yadgar | M3: Mitchell | Q3: TEMA | R3: KOMMENTARER
Q4: 1 | R4: Stor skjevdeling av innskutt kapital og lån til selskapene
A5: EIENDELER | B5: ='PLANTEDAMP AS 2022-2025'!Q9 -> 1146318.8 | C5: ='GRO PRO AS 2024 OG 2025 '!M10 -> 366362.42 | D5: =B5+C5 -> 1512681.2 | E5: =B5/2 -> 573159.39 | F5: =B5/2 -> 573159.39 | G5: =C5 -> 366362.42 | H5: =E5/D5 -> 0.37890296 | I5: =F5/D5 -> 0.37890296 | J5: =G5/D5 -> 0.24219407 | K5: =D5/3 -> 504227.07 | L5: =D5/3 -> 504227.07 | M5: =D5/3 -> 504227.07 | N5: =B5/3 -> 382106.26 | O5: =C5/3 -> 122120.81 | P5: =D5/3 -> 504227.07 | Q5: 2 | R5: Ingen har tatt ut lønn i selskapene fra etablering. Skal tema arbeidsinnsats inn i vurdering
Q6: 3 | R6: Programvare NETTBUTIKKER . Tema bør løftes . PD har hatt minimale kostnader her AU har levert GRO PRO har tatt all kost over driften
A7: INNSKUTT EGENKAPITAL pr. 31 12 2025 | B7: =-'PLANTEDAMP AS 2022-2025'!T28 -> 120000 | C7: ='GRO PRO AS 2024 OG 2025 '!P10 -> 448000 | D7: =B7+C7 -> 568000 | E7: 60000 | F7: 60000 | G7: 448000 | H7: =E7/D7 -> 0.1056338 | I7: =F7/D7 -> 0.1056338 | J7: =G7/D7 -> 0.78873239 | K7: =D7/3 -> 189333.33 | L7: =D7/3 -> 189333.33 | M7: =D7/3 -> 189333.33 | N7: =B7/3 -> 40000 | O7: =C7/3 -> 149333.33 | P7: =D7/3 -> 189333.33 | Q7: 4 | R7: Skal etablert omsetning og markedsposisjoner tas inn i vurdering
A8: RESULTAT AKK. 31 12 2025 | B8: =-'PLANTEDAMP AS 2022-2025'!R30 -> 212022.73 | C8: ='GRO PRO AS 2024 OG 2025 '!Q10 -> -372432.78 | D8: =B8+C8 -> -160410.05 | E8: =B8/2 -> 106011.37 | F8: =B8/2 -> 106011.37 | G8: =D8 -> -160410.05 | H8: =E8/D8 -> -0.66087733 | I8: =F8/D8 -> -0.66087733 | J8: =G8/D8 -> 1 | K8: =D8/3 -> -53470.017 | L8: =D8/3 -> -53470.017 | M8: =D8/3 -> -53470.017 | N8: =B8/3 -> 70674.243 | O8: =C8/3 -> -124144.26 | P8: =D8/3 -> -53470.017 | Q8: 5 | R8: GRO PRO sitt regnskap før 2024 er feil, ikke bygget inn varebeholding 31 12 2024
A9: BOKFØRT EK | B9: =B7+B8 -> 332022.73 | C9: =C7+C8 -> 75567.22 | D9: =D7+D8 -> 407589.95 | E9: =E7+E8 -> 166011.37 | F9: =F7+F8 -> 166011.37 | G9: =G7+G8 -> 287589.95 | H9: =E9/D9 -> 0.40729995 | I9: =F9/D9 -> 0.40729995 | J9: =G9/D9 -> 0.70558646 | K9: =D9/3 -> 135863.32 | L9: =D9/3 -> 135863.32 | M9: =D9/3 -> 135863.32 | N9: =B9/3 -> 110674.24 | O9: =C9/3 -> 25189.073 | P9: =D9/3 -> 135863.32 | Q9: 6 | R9: Innlån fra aksjonærer bør vurderes konvertert til egenkapital , vil da spare finansielle kostnader .
A10: Innlån fra Anders | B10: =-'PLANTEDAMP AS 2022-2025'!V45 -> 420276.66 | D10: =B10+C10 -> 420276.66 | E10: =D10 -> 420276.66 | H10: =D10/D14 -> 0.57834312 | I10: 0 | J10: 0 | K10: =D10/3 -> 140092.22 | L10: =D10/3 -> 140092.22 | M10: =D10/3 -> 140092.22 | N10: =B10/3 -> 140092.22 | O10: =C10/3 -> 0 | P10: =D10/3 -> 140092.22 | Q10: 7 | R10: Det vil være behov for mer arbeidskapital i selskapene for å kunne ta dette videre .
A11: Innlån fra Yadgar | B11: =-'PLANTEDAMP AS 2022-2025'!V44 -> 206414.2 | D11: =B11+C11 -> 206414.2 | F11: =D11 -> 206414.2 | H11: 0 | I11: =D11/D14 -> 0.28404678 | J11: 0 | K11: =D11/3 -> 68804.733 | L11: =D11/3 -> 68804.733 | M11: =D11/3 -> 68804.733 | N11: =B11/3 -> 68804.733 | O11: =C11/3 -> 0 | P11: =D11/3 -> 68804.733 | Q11: 8 | R11: Roller, avlønning i selskapene. Når vil selskapene har evne til å betale lønn for arbeidsinnsats fra aksjonærene
A12: Innlån fra Omnishop | B12: =-'PLANTEDAMP AS 2022-2025'!V32 -> 50000 | D12: =B12+C12 -> 50000 | E12: =D12 -> 50000 | H12: =D12/D14 -> 0.068805049 | I12: 0 | J12: 0 | K12: =D12/3 -> 16666.667 | L12: =D12/3 -> 16666.667 | M12: =D12/3 -> 16666.667 | N12: =B12/3 -> 16666.667 | O12: =C12/3 -> 0 | P12: =D12/3 -> 16666.667 | Q12: 9 | R12: Så langt basert på frivilling dugnad , hvilken forventninger og målsettinger har eierne med investering
A13: Innlån fra Mitchell | B13: 0 | C13: ='GRO PRO AS 2024 OG 2025 '!R10 -> 50000 | D13: =B13+C13 -> 50000 | G13: =D13 -> 50000 | H13: 0 | I13: 0 | J13: =D13/D14 -> 0.068805049 | K13: =D13/3 -> 16666.667 | L13: =D13/3 -> 16666.667 | M13: =D13/3 -> 16666.667 | N13: =B13/3 -> 0 | O13: =C13/3 -> 16666.667 | P13: =D13/3 -> 16666.667 | Q13: 10 | R13: Ukurans lager , se foreløpig vurdering
A14: INNLÅN FRA AKSJONÆRER 31 12 2025 | B14: =SUM(B10:B13) -> 676690.86 | C14: =SUM(C10:C13) -> 50000 | D14: =SUM(D10:D13) -> 726690.86 | E14: =SUM(E10:E13) -> 470276.66 | F14: =SUM(F10:F13) -> 206414.2 | G14: =SUM(G10:G13) -> 50000 | H14: =E14/D14 -> 0.64714817 | I14: =F14/D14 -> 0.28404678 | J14: =G14/D14 -> 0.068805049 | K14: =D14/3 -> 242230.29 | L14: =D14/3 -> 242230.29 | M14: =D14/3 -> 242230.29 | N14: =B14/3 -> 225563.62 | O14: =C14/3 -> 16666.667 | P14: =D14/3 -> 242230.29 | Q14: 11 | R14: Avsetning til tap på fordringer , se foreløpig vurdering
Q15: 12 | R15: Fremtidige roller, daglig ledelse av selskapene. Antar at alle 3 blir sittende i styre .
A16: EGENKAPITAL + INNLÅN | B16: =B14+B9 -> 1008713.6 | C16: =C14+C9 -> 125567.22 | D16: =D14+D9 -> 1134280.8 | E16: =E14+E9 -> 636288.03 | F16: =F14+F9 -> 372425.57 | G16: =G14+G9 -> 337589.95 | H16: =E16/D16 -> 0.56096164 | I16: =F16/D16 -> 0.3283363 | J16: =G16/D16 -> 0.29762467 | K16: =D16/3 -> 378093.6 | L16: =D16/3 -> 378093.6 | M16: =D16/3 -> 378093.6 | N16: =B16/3 -> 336237.86 | O16: =C16/3 -> 41855.74 | P16: =D16/3 -> 378093.6 | Q16: 13 | R16: Vurder å etablere et FELLES HOLDING selskap på topp, som så eier 100 % av driftsselskapene
Q17: 14 | R17: Låneavtaler ,betingelser , er det mulig å likestille aksjonærene med innskutt EGENKAPITAL
A18: INTERNT MELLOMVÆRENDE SELSKAP | B18: ='PLANTEDAMP AS 2022-2025'!X15 -> 194616.71 | C18: =-B18 -> -194616.71 | D18: =B18+C18 -> 0 | E18: =B18/2 -> 97308.355 | F18: =B18/2 -> 97308.355 | G18: =C18 -> -194616.71 | H18: =E18/B18 -> 0.5 | I18: =F18/B18 -> 0.5 | J18: =-G18/C18 -> -1 | K18: 0 | L18: 0 | M18: 0 | N18: =B18/3 -> 64872.237 | O18: =C18/3 -> -64872.237 | P18: =D18/3 -> 0 | Q18: 15 | R18: Obs, regelverk skjermingsrente . Dumt å beskatte ekstra for renter når selskapets evne til å betjene renten fortløpende er begrenset ?
Q19: 16 | R19: Det er belastet en rente på NOK 130 998,- for innlån fra aksjonærene i Plantedamp 10,5 % rente , beregnet tilbak til oppstart
A20: NETTO INNSKUTT KAPITAL (EK- LÅN OG INTERNE MV) | B20: =B16+B18 -> 1203330.3 | C20: =C16+C18 -> -69049.49 | D20: =D16+D18 -> 1134280.8 | E20: =E16+E18 -> 733596.38 | F20: =F16+F18 -> 469733.92 | G20: =G16+G18 -> 142973.24 | H20: =E20/D20 -> 0.64675023 | I20: =F20/D20 -> 0.41412489 | J20: =G20/D20 -> 0.12604748 | K20: =D20/3 -> 378093.6 | L20: =D20/3 -> 378093.6 | M20: =D20/3 -> 378093.6 | N20: =B20/3 -> 401110.1 | O20: =C20/3 -> -23016.497 | P20: =D20/3 -> 378093.6 | Q20: 17 | R20: Målsetting for selskapene 2026 -2028 , fortsatt dugnad /hobbyvirksomhet eller klare planer om vekst og inntjening
Q21: 18 | R21: Har dere gjort dere opp tanker rundt budsjett 2026. Hva ligger det i synergier i case
A22: GJELD TOTALT SELSKAP 31 12 2025 | B22: =-'PLANTEDAMP AS 2022-2025'!S9 -> 814296.05 | C22: =-'GRO PRO AS 2024 OG 2025 '!O10 -> 296579.2 | D22: =B22+C22 -> 1110875.2 | E22: =B22/2 -> 407148.02 | F22: =E22 -> 407148.02 | G22: =C22 -> 296579.2 | H22: =E22/D22 -> 0.36651102 | I22: =F22/D22 -> 0.36651102 | J22: =G22/D22 -> 0.26697795 | K22: =D22/3 -> 370291.75 | L22: =D22/3 -> 370291.75 | M22: =D22/3 -> 370291.75 | N22: =B22/3 -> 271432.02 | O22: =C22/3 -> 98859.733 | P22: =D22/3 -> 370291.75 | Q22: 19
A23: GJELD EKSTERN 31 12 2025 | B23: =B22-B14 -> 137605.19 | C23: =C22-C14+C18 -> 51962.49 | D23: =B23+C23 -> 189567.68 | E23: =B23/2 -> 68802.595 | F23: =E23 -> 68802.595 | G23: =C23 -> 51962.49 | H23: =E23/D23 -> 0.36294475 | I23: =F23/D23 -> 0.36294475 | J23: =G23/D23 -> 0.27411049 | K23: =D23/3 -> 63189.227 | L23: =D23/3 -> 63189.227 | M23: =D23/3 -> 63189.227 | N23: =B23/3 -> 45868.397 | O23: =C23/3 -> 17320.83 | P23: =D23/3 -> 63189.227 | Q23: 20
Q24: 21
Q25: 22
Q26: 23
Q27: 24
Q28: 25
Q29: 26
Q30: 27
Q31: 28
Q32: 29
Q33: 30
Q34: 31
Q35: 32
Q36: 33

Sheet PLANTEDAMP AS 2022-2025
B1: ='NØKKELTALL OVERORDNET AVTALE '!A2 -> 46031 | I1: NØKKELTALL | L1: Resultat 2022 | M1: Resultat 2023 | N1: Resultat 2024 | O1: Resultat 2025 | P1: Res. Fra etablering
I2: Salgsinntekter | L2: =-SUM(L47:L51) -> 0 | M2: =-SUM(M47:M51) -> 1149863.5 | N2: =-SUM(N47:N51) -> 1638755.2 | O2: =-SUM(O47:O51) -> 2798754.8 | P2: =-SUM(P47:P51) -> 5587373.5
I3: Vareforbruk | L3: =-SUM(L52:L60) -> -18483.77 | M3: =-SUM(M52:M60) -> -903780.43 | N3: =-SUM(N52:N60) -> -1039214.6 | O3: =-SUM(O52:O60) -> -1742941.1 | P3: =-SUM(P52:P60) -> -3704419.9
I4: Brutto kroner | L4: =L2+L3 -> -18483.77 | M4: =M2+M3 -> 246083.04 | N4: =N2+N3 -> 599540.61 | O4: =O2+O3 -> 1055813.7 | P4: =P2+P3 -> 1882953.6
I5: Brutto % | L5: =L4/L2 -> #DIV/0! | M5: =M4/M2 -> 0.21401066 | N5: =N4/N2 -> 0.36585122 | O5: =O4/O2 -> 0.3772441 | P5: =P4/P2 -> 0.33700156
I6: Driftskostnader | L6: =SUM(L61:L109) -> 11712.26 | M6: =SUM(M61:M109) -> 271597.72 | N6: =SUM(N61:N109) -> 514894.13 | O6: =SUM(O61:O109) -> 684389.71 | P6: =SUM(P61:P109) -> 1482593.8
I7: Driftskostnader i % av inntekter | L7: =L6/L2 -> #DIV/0! | M7: =M6/M2 -> 0.23619997 | N7: =N6/N2 -> 0.31419831 | O7: =O6/O2 -> 0.24453364 | P7: =P6/P2 -> 0.26534718
C9: =SUM(C11:C118) -> 0 | D9: =SUM(D11:D118) -> 4.7293724e-11 | E9: =SUM(E11:E118) -> 1.3096724e-10 | F9: =SUM(F11:F118) -> 3.1832315e-11 | G9: =SUM(G11:G118) -> 5.3478288e-10 | H9: =SUM(H11:H118) -> 6.9121597e-11 | I9: =SUM(I11:I118) -> -2.910383e-11 | J9: =SUM(J11:J118) -> 0 | L9: =-SUM(L11:L116) -> -30196.03 | M9: =-SUM(M11:M116) -> -27393.34 | N9: =-SUM(N11:N116) -> 74123.08 | O9: =-SUM(O11:O116) -> 201059.02 | P9: =-SUM(P11:P116) -> 217592.73 | Q9: =SUM(Q11:Q116) -> 1146318.8 | R9: =-SUM(R11:R116) -> 332022.73 | S9: =SUM(S11:S116) -> -814296.05 | T9: =-SUM(T11:T116) -> 120000 | U9: =-SUM(U11:U116) -> 212022.73 | V9: =-SUM(V11:V116) -> 676690.86 | W9: =-SUM(W11:W116) -> 796690.86 | X9: =SUM(X11:X116) -> 194616.71 | Y9: =SUM(Y11:Y116) -> 325022.73 | Z9: =SUM(Z11:Z116) -> -64508.75 | AA9: =SUM(AA11:AA116) -> 757096.88
A10: Kontonr | B10: Konto | C10: 31 12 2022 | D10: 31 12 2023 | E10: 31 12 2024 | F10: IB 010125 | G10: Bev 2025 | H10: UB 31 12 2025 | I10: Korreksjon 2025 | J10: 31 12 2025 | K10: Avstemt til | L10: Resultat 2022 | M10: Resultat 2023 | N10: Resultat 2024 | O10: Resultat 2025 | P10: Res. Fra etablering | Q10: Eiendeler 2025 | R10: Egenkapital | S10: Gjeld totalt | T10: Innskutt EK | U10: Res. fra etablering | V10: Innskutt lån | W10: Innskutt totalt | X10: Internt selskaper | Y10: Arbeidskapital | Z10: Eks. int og lager | AA10: Eks. inter med lager | AB10: Kommentarer Svein
A11: 1396 | B11: Depositum | C11: 0 | D11: 0 | E11: 7000 | F11: 7000 | G11: 0 | H11: =F11+G11 -> 7000 | I11: 0 | J11: =H11+I11 -> 7000 | Q11: =J11 -> 7000 | Y11: 0 | Z11: 0 | AA11: 0
A12: 1461 | B12: Varelager: Varer for videresalg, emballasje og demonstrasjonsvarer | C12: 32991.61 | D12: 324647.29 | E12: 430000.29 | F12: 430000.29 | G12: 446605.34 | H12: =F12+G12 -> 876605.63 | I12: -55000 | J12: =H12+I12 -> 821605.63 | Q12: =J12 -> 821605.63 | Y12: =Q12 -> 821605.63 | Z12: 0 | AA12: =Y12 -> 821605.63 | AB12: Korrirert telleresultat
A13: 1462 | B13: Innkjøpte ikke mottatte varer for videresalg | C13: 0 | D13: -100 | E13: 34858.02 | F13: 34858.02 | G13: -34858.02 | H13: =F13+G13 -> 0 | I13: 0 | J13: =H13+I13 -> 0 | Q13: =J13 -> 0 | Y13: 0 | Z13: 0 | AA13: =Z13 -> 0
A14: 1463 | B14: Nedskriving varelager for ukurans | C14: 0 | D14: 0 | E14: 0 | F14: 0 | G14: 0 | H14: =F14+G14 -> 0 | I14: 0 | J14: =H14+I14 -> 0 | Q14: =J14 -> 0 | Y14: =Q14 -> 0 | Z14: 0 | AA14: =Q14 -> 0 | AB14: Ukurans er håndtert via telling og fortløpende
A15: 1500 | B15: Kundefordringer | C15: 0 | D15: 24829.7 | E15: 192774.2 | F15: 192774.2 | G15: 75926.25 | H15: =F15+G15 -> 268700.45 | I15: 55000 | J15: =H15+I15 -> 323700.45 | Q15: =J15 -> 323700.45 | X15: =139616.71+55000 -> 194616.71 | Y15: =Q15 -> 323700.45 | Z15: =Y15-X15 -> 129083.74 | AA15: =Z15 -> 129083.74 | AB15: Tatt inn ekstra Kr 50 000 mot GRO PRO
A16: 1580 | B16: Avsetning til tap på fordringer | C16: 0 | D16: 0 | E16: 0 | F16: 0 | G16: 0 | H16: =F16+G16 -> 0 | I16: -50000 | J16: =H16+I16 -> -50000 | Q16: =J16 -> -50000 | Y16: =Q16 -> -50000 | Z16: -50000 | AA16: =Z16 -> -50000 | AB16: Avsetning tap på fordringer 31 12 2025
A17: 1521 | B17: Oppgjør av betaling - BankAxept | C17: 0 | D17: 277.5 | E17: -3156.97 | F17: -3156.97 | G17: -4255.79 | H17: =F17+G17 -> -7412.76 | I17: 0 | J17: =H17+I17 -> -7412.76 | Q17: =J17 -> -7412.76 | Y17: =Q17 -> -7412.76 | Z17: =Y17 -> -7412.76 | AA17: =Z17 -> -7412.76
A18: 1522 | B18: Oppgjør av betaling - Forskudd til bankkonto | C18: 0 | D18: -588 | E18: -12489.04 | F18: -12489.04 | G18: 10202.21 | H18: =F18+G18 -> -2286.83 | I18: 0 | J18: =H18+I18 -> -2286.83 | Q18: =J18 -> -2286.83 | Y18: =Q18 -> -2286.83 | Z18: =Y18 -> -2286.83 | AA18: =Z18 -> -2286.83
A19: 1523 | B19: Oppgjør av betaling - Kredittkort terminal | C19: 0 | D19: 0 | E19: 0 | F19: 0 | G19: 2660 | H19: =F19+G19 -> 2660 | I19: 0 | J19: =H19+I19 -> 2660 | Q19: =J19 -> 2660 | Y19: =Q19 -> 2660 | Z19: =Y19 -> 2660 | AA19: =Z19 -> 2660
A20: 1575 | B20: Mellomregning aksjonær/deltaker | C20: -48861.88 | D20: -175349.25 | E20: 0 | F20: 0 | G20: 0 | H20: =F20+G20 -> 0 | I20: 0 | J20: =H20+I20 -> 0 | Q20: =J20 -> 0 | Y20: =Q20 -> 0 | Z20: =Y20 -> 0 | AA20: =Z20 -> 0
A21: 1577 | B21: Mellomregning Anders Ulveseth | C21: 0 | D21: -64475.57 | E21: 0 | F21: 0 | G21: 0 | H21: =F21+G21 -> 0 | I21: 0 | J21: =H21+I21 -> 0 | Q21: =J21 -> 0 | Y21: =Q21 -> 0 | Z21: =Y21 -> 0 | AA21: =Z21 -> 0
A22: 1749 | B22: Andre forskuddsbetalte driftskostnader | C22: 0 | D22: 0 | E22: 0 | F22: 0 | G22: 200 | H22: =F22+G22 -> 200 | I22: 0 | J22: =H22+I22 -> 200 | Q22: =J22 -> 200 | Y22: =Q22 -> 200 | Z22: =Y22 -> 200 | AA22: =Z22 -> 200
A23: 1901 | B23: Mynter og sedler | C23: 0 | D23: 918 | E23: 2103 | F23: 2103 | G23: -622 | H23: =F23+G23 -> 1481 | I23: 0 | J23: =H23+I23 -> 1481 | Q23: =J23 -> 1481 | Y23: =Q23 -> 1481 | Z23: =Y23 -> 1481 | AA23: =Z23 -> 1481
A24: 1909 | B24: Kassedifferanse | C24: 0 | D24: 70 | E24: 5952.7 | F24: 5952.7 | G24: -1979.72 | H24: =F24+G24 -> 3972.98 | I24: 0 | J24: =H24+I24 -> 3972.98 | Q24: =J24 -> 3972.98 | Y24: =Q24 -> 3972.98 | Z24: =Y24 -> 3972.98 | AA24: =Z24 -> 3972.98
A25: 19201 | B25: Driftskonto SPV 3626.36.30208 (36263630208) | C25: 38334.41 | D25: 72446.85 | E25: 29810.28 | F25: 29810.28 | G25: 8633.03 | H25: =F25+G25 -> 38443.31 | I25: 0 | J25: =H25+I25 -> 38443.31 | K25: 23.12.2025 | Q25: =J25 -> 38443.31 | Y25: =Q25 -> 38443.31 | Z25: =Y25 -> 38443.31 | AA25: =Z25 -> 38443.31
A26: 19501 | B26: Skattetrekkskonto SPV (36263687536) | C26: 0 | D26: 0 | E26: 10166 | F26: 10166 | G26: -8070 | H26: =F26+G26 -> 2096 | I26: 0 | J26: =H26+I26 -> 2096 | K26: 18.12.2025 | Q26: =J26 -> 2096 | Y26: =Q26 -> 2096 | Z26: =Y26 -> 2096 | AA26: =Z26 -> 2096
A27: 19601 | B27: Krypto - Coinbase Commerce (KRYPTO) | C27: 0 | D27: 0 | E27: 696 | F27: 696 | G27: 4163 | H27: =F27+G27 -> 4859 | I27: 0 | J27: =H27+I27 -> 4859 | Q27: =J27 -> 4859 | Y27: =Q27 -> 4859 | Z27: =Y27 -> 4859 | AA27: =Z27 -> 4859
A28: 2000 | B28: Aksjekapital / Egenkapital, bundet | C28: -60000 | D28: -120000 | E28: -120000 | F28: -120000 | G28: 0 | H28: =F28+G28 -> -120000 | I28: 0 | J28: =H28+I28 -> -120000 | R28: =J28 -> -120000 | T28: =R28 -> -120000 | W28: =T28 -> -120000 | Z28: 0 | AA28: =Z28 -> 0
A29: 2036 | B29: Stiftelseskostnader | C29: 5570 | D29: 0 | E29: 0 | F29: 0 | G29: 0 | H29: =F29+G29 -> 0 | I29: 0 | J29: =H29+I29 -> 0 | R29: =J29 -> 0 | Z29: 0 | AA29: =Z29 -> 0
A30: 2050 | B30: Annen egenkapital | C30: 0 | D30: 0 | E30: -10963.71 | F30: -10963.71 | G30: 0 | H30: =F30+G30 -> -10963.71 | I30: =-O9 -> -201059.02 | J30: =H30+I30 -> -212022.73 | R30: =J30 -> -212022.73 | U30: =R30 -> -212022.73 | Z30: 0 | AA30: =Z30 -> 0 | AB30: Diffeanse Kr 5 570, stiftelsekost mot annen Ek
A31: 2080 | B31: Udekket tap | C31: 30196.03 | D31: 63159.37 | E31: 0 | F31: 0 | G31: 0 | H31: =F31+G31 -> 0 | I31: 0 | J31: =H31+I31 -> 0 | R31: =J31 -> 0 | Z31: 0 | AA31: =Z31 -> 0
A32: 2400 | B32: Leverandørgjeld | C32: -10367.17 | D32: -75258.89 | E32: -244456.97 | F32: -244456.97 | G32: 233263.1 | H32: =F32+G32 -> -11193.87 | I32: 0 | J32: =H32+I32 -> -11193.87 | S32: =J32 -> -11193.87 | V32: -50000 | W32: =V32 -> -50000 | Y32: =S32 -> -11193.87 | Z32: =Y32 -> -11193.87 | AA32: =Z32 -> -11193.87 | AB32: Kortsiktig lån fra Omnishop AS /Anderse
A33: 2500 | B33: Betalbar skatt, ikke fastsatt | C33: 0 | D33: 0 | E33: -3105 | F33: -3105 | G33: 0 | H33: =F33+G33 -> -3105 | I33: =-I116 -> -56708.96 | J33: =H33+I33 -> -59813.96 | S33: =J33 -> -59813.96 | Y33: =S33 -> -59813.96 | Z33: =Y33 -> -59813.96 | AA33: =Z33 -> -59813.96 | AB33: Foreløpig beregnet skatt
A34: 2600 | B34: Forskuddstrekk (skatt på lønn) | C34: 0 | D34: 0 | E34: -10166 | F34: -10166 | G34: 8070 | H34: =F34+G34 -> -2096 | I34: 0 | J34: =H34+I34 -> -2096 | S34: =J34 -> -2096 | Y34: =S34 -> -2096 | Z34: =Y34 -> -2096 | AA34: =Z34 -> -2096
A35: 2701 | B35: Utgående mva, høy sats | C35: 0 | D35: 0 | E35: 0 | F35: 0 | G35: -215144.06 | H35: =F35+G35 -> -215144.06 | I35: 0 | J35: =H35+I35 -> -215144.06 | S35: =J35 -> -215144.06 | Y35: =S35 -> -215144.06 | Z35: =Y35 -> -215144.06 | AA35: =Z35 -> -215144.06
A36: 2702 | B36: Utgående mva, kjøp tjenester fra utlandet | C36: 0 | D36: 0 | E36: 0 | F36: 0 | G36: -173.96 | H36: =F36+G36 -> -173.96 | I36: 0 | J36: =H36+I36 -> -173.96 | S36: =J36 -> -173.96 | Y36: =S36 -> -173.96 | Z36: =Y36 -> -173.96 | AA36: =Z36 -> -173.96
A37: 2703 | B37: Utgående mva, middels sats | C37: 0 | D37: 0 | E37: 0 | F37: 0 | G37: -646.54 | H37: =F37+G37 -> -646.54 | I37: 0 | J37: =H37+I37 -> -646.54 | S37: =J37 -> -646.54 | Y37: =S37 -> -646.54 | Z37: =Y37 -> -646.54 | AA37: =Z37 -> -646.54
A38: 2711 | B38: Inngående mva, høy sats | C38: 0 | D38: 0 | E38: 0 | F38: 0 | G38: 110536.85 | H38: =F38+G38 -> 110536.85 | I38: 0 | J38: =H38+I38 -> 110536.85 | S38: =J38 -> 110536.85 | Y38: =S38 -> 110536.85 | Z38: =Y38 -> 110536.85 | AA38: =Z38 -> 110536.85
A39: 2712 | B39: Inngående mva, kjøp tjenester fra utlandet | C39: 0 | D39: 0 | E39: 0 | F39: 0 | G39: 173.96 | H39: =F39+G39 -> 173.96 | I39: 0 | J39: =H39+I39 -> 173.96 | S39: =J39 -> 173.96 | Y39: =S39 -> 173.96 | Z39: =Y39 -> 173.96 | AA39: =Z39 -> 173.96
A40: 2740 | B40: Oppgjørskonto mva (gjeld) | C40: 12137 | D40: -34187 | E40: -62478 | F40: -62478 | G40: 67815 | H40: =F40+G40 -> 5337 | I40: 0 | J40: =H40+I40 -> 5337 | S40: =J40 -> 5337 | Y40: =S40 -> 5337 | Z40: =Y40 -> 5337 | AA40: =Z40 -> 5337
A41: 2771 | B41: Skyldig arbeidsgiveravgift | C41: 0 | D41: 0 | E41: -4073 | F41: -4073 | G41: 1917 | H41: =F41+G41 -> -2156 | I41: 0 | J41: =H41+I41 -> -2156 | S41: =J41 -> -2156 | Y41: =S41 -> -2156 | Z41: =Y41 -> -2156 | AA41: =Z41 -> -2156
...

Sheet GRO PRO AS 2024 OG 2025 
B1: ='NØKKELTALL OVERORDNET AVTALE '!A2 -> 46031
G2: NØKKELTALL | J2: Resultat 2024 | K2: Resultat 2025 | L2: Res. Fra etablering
G3: Salgsinntekter | J3: =-SUM(J27:J28) -> 96973.39 | K3: =-SUM(K27:K28) -> 613516.26 | L3: =-SUM(L27:L28) -> 710489.65
G4: Vareforbruk | J4: =-SUM(J29:J35) -> -212215.97 | K4: =-SUM(K29:K35) -> -475426 | L4: =-SUM(L29:L35) -> -687641.97
G5: Brutto kroner | J5: =J3+J4 -> -115242.58 | K5: =K3+K4 -> 138090.26 | L5: =L3+L4 -> 22847.68
G6: Brutto % | J6: =J5/J3 -> -1.1883938 | K6: =K5/K3 -> 0.22508003 | L6: =L5/L3 -> 0.032157654
G7: Driftskostnader | J7: =SUM(J36:J48) -> 151287.26 | K7: =SUM(K36:K48) -> 239883.18 | L7: =SUM(L36:L48) -> 391170.44
G8: Driftskostnader i % av inntekter | J8: =J7/J3 -> 1.5600905 | K8: =K7/K3 -> 0.39099727 | L8: =L7/L3 -> 0.55056459
B10: SUM FILTER UTVALG | C10: =-SUBTOTAL(9,C12:C401) -> 0 | D10: =-SUBTOTAL(9,D12:D401) -> 0 | E10: =-SUBTOTAL(9,E12:E401) -> 4.5474735e-13 | F10: =-SUBTOTAL(9,F12:F401) -> 4.5474735e-13 | G10: =-SUBTOTAL(9,G12:G401) -> 0 | H10: =-SUBTOTAL(9,H12:H401) -> 0 | I10: =-SUBTOTAL(9,I12:I401) -> 0 | J10: =-SUBTOTAL(9,J12:J401) -> -266860.46 | ... L10: =-SUBTOTAL(9,L12:L401) -> -372432.78 | M10: =SUBTOTAL(9,M12:M401) -> 366362.42 | N10: =-SUBTOTAL(9,N12:N401) -> 69783.22 | O10: =SUBTOTAL(9,O12:O401) -> -296579.2 | P10: =-SUBTOTAL(9,P12:P401) -> 448000 | Q10: =-SUBTOTAL(9,Q12:Q401) -> -372432.78 | R10: =-SUBTOTAL(9,R12:R401) -> 50000 | S10: =-SUBTOTAL(9,S12:S401) -> 498000 | T10: =SUBTOTAL(9,T12:T401) -> -194616 | U10: =SUBTOTAL(9,U12:U401) -> 69783.22 | V10: =SUBTOTAL(9,V12:V401) -> -10713.63 | W10: =SUBTOTAL(9,W12:W401) -> 314399.22
A11: Kontonr | B11: Konto | C11: SB 31 12 2024 | D11: IB 010125 | E11: Bevegelse 2025 | F11: UB 31 12 2025 | G11: Korreksjon 2025 | H11: 31 12 2025 | I11: Avstemt til | J11: Resultat 2024 | K11: Resultat 2025 | L11: Res. Fra etablering | M11: Eiendeler 2025 | N11: Egenkapital | O11: Gjeld totalt | P11: Innskutt EK | Q11: Res. fra etablering | R11: Innskutt lån | S11: Innskutt totalt | T11: Internt selskaper | U11: Arbeidskapital | V11: Eks. intern og lager | W11: Eks intern med lager | X11: Kommentarer Svein
A12: 1461 | B12: Varelager: Varer for videresalg, emballasje og demonstrasjonsvarer | C12: 0 | D12: 0 | E12: 325112.85 | F12: =D12+E12 -> 325112.85 | G12: 0 | H12: =F12+G12 -> 325112.85 | M12: =H12 -> 325112.85 | N12: 0 | O12: 0 | P12: 0 | Q12: 0 | R12: 0 | S12: 0 | T12: 0 | U12: =M12 -> 325112.85 | V12: 0 | W12: =U12 -> 325112.85 | X12: Overføring av lager fra PD er med i lager
A13: 1463 | B13: Nedskriving lager for ukurans | C13: 0 | D13: 0 | E13: 0 | F13: =D13+E13 -> 0 | G13: 0 | H13: =F13+G13 -> 0 | M13: =H13 -> 0 | N13: 0 | O13: 0 | P13: 0 | Q13: 0 | R13: 0 | S13: 0 | T13: 0 | U13: =H13 -> 0 | V13: 0 | W13: =U13 -> 0 | X13: Vurder kurans lager
A14: 1500 | B14: Kundefordringer | C14: 0 | D14: 0 | E14: 43023 | F14: =D14+E14 -> 43023 | G14: 0 | H14: =F14+G14 -> 43023 | M14: =H14 -> 43023 | N14: 0 | O14: 0 | P14: 0 | Q14: 0 | R14: 0 | S14: 0 | T14: 43023 | U14: =M14 -> 43023 | V14: 0 | W14: 0 | X14: fordring mot PD ref. fakturering overføring lager
A15: 19201 | B15: Driftskonto (36062185605) | C15: 64404.21 | D15: 64404.21 | E15: -66177.64 | F15: =D15+E15 -> -1773.43 | G15: 0 | H15: =F15+G15 -> -1773.43 | I15: 30.11.2025 | M15: =H15 -> -1773.43 | N15: 0 | O15: 0 | P15: 0 | Q15: 0 | R15: 0 | S15: 0 | T15: 0 | U15: =M15 -> -1773.43 | V15: =U15 -> -1773.43 | W15: =V15 -> -1773.43
A16: 19202 | B16: Folio-kort (36062185613) | C16: 5660.33 | D16: 5660.33 | E16: -5660.33 | F16: =D16+E16 -> 0 | G16: 0 | H16: =F16+G16 -> 0 | I16: 30.11.2025 | M16: =H16 -> 0 | N16: 0 | O16: 0 | P16: 0 | Q16: 0 | R16: 0 | S16: 0 | T16: 0 | U16: 0 | V16: =U16 -> 0 | W16: 0
A17: 2000 | B17: Aksjekapital / Egenkapital, bundet | C17: -30000 | D17: -30000 | E17: 0 | F17: =D17+E17 -> -30000 | G17: 0 | H17: =F17+G17 -> -30000 | M17: 0 | N17: =H17 -> -30000 | O17: 0 | P17: =N17 -> -30000 | Q17: 0 | R17: 0 | S17: =P17+R17 -> -30000 | T17: 0 | U17: 0 | V17: =U17 -> 0 | W17: 0
A18: 2020 | B18: Overkurs | C18: -358000 | D18: -358000 | E18: 0 | F18: =D18+E18 -> -358000 | G18: 0 | H18: =F18+G18 -> -358000 | M18: 0 | N18: =H18 -> -358000 | O18: 0 | P18: =N18 -> -358000 | Q18: 0 | R18: 0 | S18: =P18+R18 -> -358000 | T18: 0 | U18: 0 | V18: =U18 -> 0 | W18: 0
A19: 2036 | B19: Stiftelsesutgifter | C19: 5784 | D19: 5784 | E19: 0 | F19: =D19+E19 -> 5784 | G19: 0 | H19: =F19+G19 -> 5784 | M19: 0 | N19: =H19 -> 5784 | O19: 0 | P19: 0 | Q19: 0 | R19: 0 | S19: =P19+R19 -> 0 | T19: 0 | U19: 0 | V19: =U19 -> 0 | W19: 0
A20: 2050 | B20: Annen egenkapital | C20: 0 | D20: 0 | E20: -60000 | F20: =D20+E20 -> -60000 | G20: 0 | H20: =F20+G20 -> -60000 | M20: 0 | N20: =H20 -> -60000 | O20: 0 | P20: =N20 -> -60000 | Q20: 0 | R20: 0 | S20: =P20+R20 -> -60000 | T20: 0 | U20: 0 | V20: =U20 -> 0 | W20: 0 | X20: Dette er et lån fra aksjonær , skulle vært flyttet til lån
A21: 2080 | B21: Udekket tap | C21: 266860.46 | D21: 266860.46 | E21: 0 | F21: =D21+E21 -> 266860.46 | G21: =-K10 -> 105572.32 | H21: =F21+G21 -> 372432.78 | M21: 0 | N21: =H21 -> 372432.78 | O21: 0 | P21: 0 | Q21: =N21 -> 372432.78 | R21: 0 | S21: =P21+R21 -> 0 | T21: 0 | U21: 0 | V21: =U21 -> 0 | W21: 0
A22: 2255 | B22: Gjeld til eiere langsiktig | C22: 0 | D22: 0 | E22: -50000 | F22: =D22+E22 -> -50000 | G22: 0 | H22: =F22+G22 -> -50000 | M22: 0 | N22: 0 | O22: =H22 -> -50000 | P22: 0 | Q22: 0 | R22: =O22 -> -50000 | S22: =P22+R22 -> -50000 | T22: 0 | U22: =O22 -> -50000 | V22: 0 | W22: 0 | X22: Er det laget låneavtale, betingelser må avklares
A23: 2400 | B23: Leverandørgjeld | C23: 0 | D23: 0 | E23: -7246.34 | F23: =D23+E23 -> -7246.34 | G23: =-182639-55000 -> -237639 | H23: =F23+G23 -> -244885.34 | M23: 0 | N23: 0 | O23: =H23 -> -244885.34 | P23: 0 | Q23: 0 | R23: 0 | S23: 0 | T23: =G23 -> -237639 | U23: =O23 -> -244885.34 | V23: =F23 -> -7246.34 | W23: =V23 -> -7246.34 | X23: Faktura fra PD ikke bokført , er dette TALT ?
A24: 2701 | B24: Utgående mva, høy sats | C24: 0 | D24: 0 | E24: -45021.95 | F24: =D24+E24 -> -45021.95 | G24: 0 | H24: =F24+G24 -> -45021.95 | M24: 0 | N24: 0 | O24: =H24 -> -45021.95 | P24: 0 | Q24: 0 | R24: 0 | S24: 0 | T24: 0 | U24: =O24 -> -45021.95 | V24: =U24 -> -45021.95 | W24: =V24 -> -45021.95
A25: 2711 | B25: Inngående mva, høy sats | C25: 0 | D25: 0 | E25: 6903.29 | F25: =D25+E25 -> 6903.29 | G25: =182639-146111.2 -> 36527.8 | H25: =F25+G25 -> 43431.09 | M25: 0 | N25: 0 | O25: =H25 -> 43431.09 | P25: 0 | Q25: 0 | R25: 0 | S25: 0 | T25: 0 | U25: =O25 -> 43431.09 | V25: =U25 -> 43431.09 | W25: =V25 -> 43431.09 | X25: Mva inngående faktura fra PD
A26: 2740 | B26: Oppgjørskonto mva (gjeld) | C26: 45291 | D26: 45291 | E26: -45394 | F26: =D26+E26 -> -103 | G26: 0 | H26: =F26+G26 -> -103 | M26: 0 | N26: 0 | O26: =H26 -> -103 | P26: 0 | Q26: 0 | R26: 0 | S26: 0 | T26: 0 | U26: =O26 -> -103 | V26: =U26 -> -103 | W26: =V26 -> -103
A27: 3000 | B27: Salgsinntekt varer, høy mva-sats | C27: -96973.39 | D27: 0 | E27: -611828.26 | F27: =D27+E27 -> -611828.26 | G27: 0 | H27: =F27+G27 -> -611828.26 | J27: =C27 -> -96973.39 | K27: =H27 -> -611828.26 | L27: =J27+K27 -> -708801.65
A28: 3200 | B28: Salgsinntekt varer, unntatt for mva | C28: 0 | D28: 0 | E28: -1688 | F28: =D28+E28 -> -1688 | G28: 0 | H28: =F28+G28 -> -1688 | J28: =C28 -> 0 | K28: =H28 -> -1688 | L28: =J28+K28 -> -1688
A29: 4000 | B29: Råvarer og halvfabrikata | C29: 0 | D29: 0 | E29: 312273.86 | F29: =D29+E29 -> 312273.86 | G29: 0 | H29: =F29+G29 -> 312273.86 | J29: =C29 -> 0 | K29: =H29 -> 312273.86 | L29: =J29+K29 -> 312273.86
A30: 4060 | B30: Frakt og toll ved mottak av råvarer og halvfabrikata | C30: 2043 | D30: 0 | E30: 19387 | F30: =D30+E30 -> 19387 | G30: 0 | H30: =F30+G30 -> 19387 | J30: =C30 -> 2043 | K30: =H30 -> 19387 | L30: =J30+K30 -> 21430
A31: 4300 | B31: Varer for videresalg | C31: 208463.47 | D31: 0 | E31: 259298.39 | F31: =D31+E31 -> 259298.39 | G31: =146111.2+55000 -> 201111.2 | H31: =F31+G31 -> 460409.59 | J31: =C31 -> 208463.47 | K31: =H31 -> 460409.59 | L31: =J31+K31 -> 668873.06 | X31: Faktura fra PD ikke bokført , er dette TALT ?
A32: 4360 | B32: Frakt og toll ved mottak av varer for videresalg | C32: 847.5 | D32: 0 | E32: 7607.6 | F32: =D32+E32 -> 7607.6 | G32: 0 | H32: =F32+G32 -> 7607.6 | J32: =C32 -> 847.5 | K32: =H32 -> 7607.6 | L32: =J32+K32 -> 8455.1
A33: 4390 | B33: Endring i varer for videresalg (kun varetelling) | C33: 0 | D33: 0 | E33: -325112.85 | F33: =D33+E33 -> -325112.85 | G33: 0 | H33: =F33+G33 -> -325112.85 | J33: =C33 -> 0 | K33: =H33 -> -325112.85 | L33: =J33+K33 -> -325112.85 | X33: Har forutsatt at faktura PD skal tilføres lager 311225
A34: 4391 | B34: Endring nedskriving for ukurans | C34: 0 | D34: 0 | E34: 0 | F34: =D34+E34 -> 0 | G34: 0 | H34: =F34+G34 -> 0 | J34: =C34 -> 0 | K34: =H34 -> 0 | L34: =J34+K34 -> 0
A35: 4600 | B35: Emballasje og pakker | C35: 862 | D35: 0 | E35: 860.8 | F35: =D35+E35 -> 860.8 | G35: 0 | H35: =F35+G35 -> 860.8 | J35: =C35 -> 862 | K35: =H35 -> 860.8 | L35: =J35+K35 -> 1722.8
A36: 6100 | B36: Frakt, transportkostnad og forsikring ved utsending av varer | C36: 4382.87 | D36: 0 | E36: 73081.65 | F36: =D36+E36 -> 73081.65 | G36: 0 | H36: =F36+G36 -> 73081.65 | J36: =C36 -> 4382.87 | K36: =H36 -> 73081.65 | L36: =J36+K36 -> 77464.52
A37: 6300 | B37: Leie lokale | C37: 0 | D37: 0 | E37: 26800 | F37: =D37+E37 -> 26800 | G37: 0 | H37: =F37+G37 -> 26800 | J37: =C37 -> 0 | K37: =H37 -> 26800 | L37: =J37+K37 -> 26800
A38: 6400 | B38: Leie maskiner | C38: 0 | D38: 0 | E38: 23828.67 | F38: =D38+E38 -> 23828.67 | G38: 0 | H38: =F38+G38 -> 23828.67 | J38: =C38 -> 0 | K38: =H38 -> 23828.67 | L38: =J38+K38 -> 23828.67
A39: 6500 | B39: Verktøy og utstyr | C39: 0 | D39: 0 | E39: 3199.2 | F39: =D39+E39 -> 3199.2 | G39: 0 | H39: =F39+G39 -> 3199.2 | J39: =C39 -> 0 | K39: =H39 -> 3199.2 | L39: =J39+K39 -> 3199.2
A40: 6540 | B40: Møbler, interiør og annet inventar | C40: 0 | D40: 0 | E40: 11729.36 | F40: =D40+E40 -> 11729.36 | G40: 0 | H40: =F40+G40 -> 11729.36 | J40: =C40 -> 0 | K40: =H40 -> 11729.36 | L40: =J40+K40 -> 11729.36
A41: 6551 | B41: Data, telefon og andre kontormaskiner | C41: 2775.2 | D41: 0 | E41: 0 | F41: =D41+E41 -> 0 | G41: 0 | H41: =F41+G41 -> 0 | J41: =C41 -> 2775.2 | K41: =H41 -> 0 | L41: =J41+K41 -> 2775.2
...
